<robot name="test_robot">
   2   <link name="link1" />
   3   <link name="link2" />
   4   <link name="link3" />
   5   <link name="link4" />
   6 
   7   <joint name="joint1" type="continuous">
   8     <parent link="link1"/>
   9     <child link="link2"/>
  10     <origin xyz="5 3 0" rpy="0 0 0" />
  11     <axis xyz="-0.9 0.15 0" />
  12   </joint>
  13 
  14   <joint name="joint2" type="continuous">
  15     <parent link="link1"/>
  16     <child link="link3"/>
  17     <origin xyz="-2 5 0" rpy="0 0 1.57" />
  18     <axis xyz="-0.707 0.707 0" />
  19   </joint>
  20 
  21   <joint name="joint3" type="continuous">
  22     <parent link="link3"/>
  23     <child link="link4"/>
  24     <origin xyz="5 0 0" rpy="0 0 -1.57" />
  25     <axis xyz="0.707 -0.707 0" />
  26   </joint>
  27 </robot>